<?xml version="1.0" ?>
<robot name="basic_mobile_bot"
  xmlns:xacro="http://ros.org/wiki/xacro">

  <!-- ****************** ROBOT CONSTANTS *******************************  -->
  <!-- Define the size of the robot's main chassis in meters -->
  <xacro:property name="base_width" value="0.45" />
  <xacro:property name="base_length" value="0.807" />
  <xacro:property name="base_height" value="0.1019" />

  <!-- Define the shape of the robot's two back wheels in meters -->
  <xacro:property name="wheel_radius" value="0.1745" />
  <xacro:property name="wheel_width" value="0.103" />

  <!-- x-axis points forward, y-axis points to left, z-axis points upwards -->
  <!-- Define the gap between the wheel and chassis along y-axis in meters -->
  <xacro:property name="wheel_track" value="0.5963"/>

  <!-- Position the wheels along the z-axis -->
  <xacro:property name="wheel_z_offset" value="-0.034"/>

  <!-- Position the wheels along the x-axis -->
  <xacro:property name="wheelbase" value="0.5"/>

  <xacro:property name="cage_offset" value=".19"/>

  <!-- Define intertial property macros  -->
  <xacro:macro name="box_inertia" params="m w h d">
    <inertial>
      <mass value="${m}"/>
      <inertia ixx="${(m/12) * (h*h + d*d)}" ixy="0.0" ixz="0.0" iyy="${(m/12) * (w*w + d*d)}" iyz="0.0" izz="${(m/12) * (w*w + h*h)}"/>
    </inertial>
  </xacro:macro>

  <xacro:macro name="cylinder_inertia" params="m r h">
    <inertial>
      <mass value="${m}"/>
      <inertia ixx="${(m/12) * (3*r*r + h*h)}" ixy = "0" ixz = "0" iyy="${(m/12) * (3*r*r + h*h)}" iyz = "0" izz="${(m/2) * (r*r)}"/>
    </inertial>
  </xacro:macro>

  <!-- ****************** ROBOT BASE FOOTPRINT ***************************  -->
  <!-- Define the center of the main robot chassis projected on the ground -->
  <link name="base_footprint"/>

  <!-- The base footprint of the robot is located underneath the chassis -->
  <joint name="base_joint" type="fixed">
    <parent link="base_link"/>
    <child link="base_footprint" />
    <origin xyz="0.0 0.0 ${(wheel_radius-wheel_z_offset)}" rpy="0 0 0"/>
  </joint>

  <!-- ********************** ROBOT BASE *********************************  -->
  <link name="base_link">
    <visual>
      <geometry>
        <mesh filename="package://basic_mobile_robot/meshes/chassis.stl" />
      </geometry>
      <material name="Yellow">
        <color rgba="${255/255} ${0/255} ${0/255} 1.0"/>
      </material>
    </visual>

    <collision>
      <geometry>
        <box size="${base_length} ${base_width} ${base_height}"/>
      </geometry>
    </collision>

    <xacro:box_inertia m="40.0" w="${base_width}" d="${base_length}" h="${base_height}"/>

  </link>

  <gazebo reference="base_link">
    <material>Gazebo/Yellow</material>
  </gazebo>

  <!-- ********************** Acessory Cage *********************************  -->
  <link name="cage_link">
    <visual>
      <geometry>
        <mesh filename="package://basic_mobile_robot/meshes/cage.stl" />
      </geometry>
      <material name="black">
        <color rgba="${0/255} ${0/255} ${0/255} 1.0"/>
      </material>
    </visual>

    <collision>
      <geometry>
        <mesh filename="package://basic_mobile_robot/meshes/cage.stl" />
      </geometry>
    </collision>

    <xacro:box_inertia m="3" w="${base_width}" d="${base_length}" h="${base_height}"/>
  </link>

  <joint name="cage_joint" type="fixed">
    <parent link="base_link"/>
    <child link="cage_link" />
    <origin xyz="0.0 0.0 .119" rpy="0 0 0"/>
  </joint>

  <gazebo reference="base_link">
    <material>Gazebo/Yellow</material>
  </gazebo>

  <!-- *********************** DRIVE WHEELS ******************************  -->

  <xacro:macro name="wheel" params="prefix x_reflect y_reflect">
    <link name="${prefix}_link">
      <visual>
        <geometry>
          <mesh filename="package://basic_mobile_robot/meshes/wheel.stl" />
        </geometry>
        <material name="black">
          <color rgba="${1/255} ${1/255} ${1/255} 1.0"/>
        </material>
      </visual>

      <collision>
        <geometry>
          <mesh filename="package://basic_mobile_robot/meshes/wheel.stl" />
        </geometry>
      </collision>

      <xacro:cylinder_inertia m="3" r="${wheel_radius}" h="${wheel_width}"/>

    </link>

    <!-- Connect the wheels to the base_link at the appropriate location, and 
         define a continuous joint to allow the wheels to freely rotate about
         an axis -->
    <joint name="${prefix}_joint" type="continuous">
      <parent link="base_link"/>
      <child link="${prefix}_link"/>
      <origin xyz="${x_reflect*wheelbase/2} ${(y_reflect*wheel_track/2)} ${wheel_z_offset}" rpy="0 0 0"/>
      <axis xyz="0 1 0"/>
    </joint>
  </xacro:macro>

  <!-- Instantiate two wheels using the macro we just made through the 
       xacro:wheel tags. We also define the parameters to have one wheel
       on both sides at the back of our robot (i.e. x_reflect=-1). -->
  <xacro:wheel prefix="front_left" x_reflect="1" y_reflect="1" />
  <xacro:wheel prefix="front_right" x_reflect="1" y_reflect="-1" />
  <xacro:wheel prefix="rear_left" x_reflect="-1" y_reflect="1" />
  <xacro:wheel prefix="rear_right" x_reflect="-1" y_reflect="-1" />

  <!-- *********************** IMU SETUP *********************************  -->
  <!-- Each sensor must be attached to a link.                              -->

  <joint name="imu_joint" type="fixed">
    <parent link="base_link"/>
    <child link="imu_link"/>
    <origin xyz="-0.10 0 0.05" rpy="0 0 0"/>
  </joint>

  <link name="imu_link"/>

  <!-- *********************** GPS SETUP **********************************  -->
  <joint name="gps_joint" type="fixed">
    <parent link="base_link"/>
    <child link="gps_link"/>
    <origin xyz="0.10 0 0.05" rpy="0 0 0"/>
  </joint>

  <link name="gps_link"/>

  <!-- *********************** LIDAR SETUP **********************************  -->
  <joint name="lidar_joint" type="fixed">
    <parent link="base_link"/>
    <child link="lidar_link"/>
    <origin xyz="0.3885 0 0.192" rpy="0 0 0"/>
  </joint>

  <link name="lidar_link">

    <collision>
      <geometry>
        <mesh filename="package://basic_mobile_robot/meshes/rplidar_s1.stl" />
      </geometry>
    </collision>

    <visual>
      <geometry>
        <mesh filename="package://basic_mobile_robot/meshes/rplidar_s1.stl" />
      </geometry>
      <material name="Black">
        <color rgba="${0/255} ${0/255} ${0/255} 1.0"/>
      </material>
    </visual>

    <inertial>
      <mass value="0.114" />
      <origin xyz="0 0 0" rpy="0 0 0"/>
      <inertia ixx="0.001" ixy="0" ixz="0" iyy="0.001" iyz="0" izz="0.001" />
    </inertial>
  </link>

</robot>